INFO     api_log:my_log.py:31 -----测试开始----
INFO     api_log:my_log.py:31 测试数据；{'username': '18684720553', 'pwd': 'python', 'expected': 'python10'}
INFO     api_log:my_log.py:31 -----测试结束----
WARNING  urllib3.connectionpool:connectionpool.py:665 Retrying (Retry(total=2, connect=None, read=None, redirect=None, status=None)) after connection broken by 'NewConnectionError('<urllib3.connection.HTTPConnection object at 0x000001ACB6063710>: Failed to establish a new connection: [WinError 10061] 由于目标计算机积极拒绝，无法连接。')': /session/5c2a95a8408fdfe38b69cd06be32a4e2
WARNING  urllib3.connectionpool:connectionpool.py:665 Retrying (Retry(total=1, connect=None, read=None, redirect=None, status=None)) after connection broken by 'NewConnectionError('<urllib3.connection.HTTPConnection object at 0x000001ACB60637B8>: Failed to establish a new connection: [WinError 10061] 由于目标计算机积极拒绝，无法连接。')': /session/5c2a95a8408fdfe38b69cd06be32a4e2
WARNING  urllib3.connectionpool:connectionpool.py:665 Retrying (Retry(total=0, connect=None, read=None, redirect=None, status=None)) after connection broken by 'NewConnectionError('<urllib3.connection.HTTPConnection object at 0x000001ACB6063860>: Failed to establish a new connection: [WinError 10061] 由于目标计算机积极拒绝，无法连接。')': /session/5c2a95a8408fdfe38b69cd06be32a4e2