INFO     api_log:my_log.py:31 -----测试开始----
INFO     api_log:my_log.py:31 测试数据；{'username': '18684720553', 'pwd': 'python', 'expected': 'python10'}
INFO     api_log:my_log.py:31 -----测试结束----
WARNING  urllib3.connectionpool:connectionpool.py:665 Retrying (Retry(total=2, connect=None, read=None, redirect=None, status=None)) after connection broken by 'NewConnectionError('<urllib3.connection.HTTPConnection object at 0x00000161910B5550>: Failed to establish a new connection: [WinError 10061] 由于目标计算机积极拒绝，无法连接。')': /session/27993688a37b82567b7f98b616007d47
WARNING  urllib3.connectionpool:connectionpool.py:665 Retrying (Retry(total=1, connect=None, read=None, redirect=None, status=None)) after connection broken by 'NewConnectionError('<urllib3.connection.HTTPConnection object at 0x00000161910B5710>: Failed to establish a new connection: [WinError 10061] 由于目标计算机积极拒绝，无法连接。')': /session/27993688a37b82567b7f98b616007d47
WARNING  urllib3.connectionpool:connectionpool.py:665 Retrying (Retry(total=0, connect=None, read=None, redirect=None, status=None)) after connection broken by 'NewConnectionError('<urllib3.connection.HTTPConnection object at 0x00000161910B5860>: Failed to establish a new connection: [WinError 10061] 由于目标计算机积极拒绝，无法连接。')': /session/27993688a37b82567b7f98b616007d47